<?xml version="1.0"?>
<robot name="Robot1">
    <!-- comentario -->
    <link name="base_link">
        <visual>
            <geometry>
                <box size="0.2 0.3 0.1"/>
            </geometry>
            <origin rpy="0 0 0" xyz="0 0 0.05"/>
            <material name="white">
                <color rgba="1 1 1 1" />
            </material>    
        </visual>
    </link>
    <link name="link_1">
        <visual>
            <geometry>
                <!-- box:  x(m) y(m) z(m)-->
                <cylinder length="0.05" radius="0.05" />
            </geometry>
            <origin rpy="0 1.5 0" xyz="0.1 0.1 0"/>
            <material name="black">
                <color rgba="0 0 0 1" />
            </material>    
        </visual>
    </link>
    <link name="link_2">
        <visual>
            <geometry>
                <cylinder radius="0.05" length="0.05"/>  
            </geometry>
            <origin rpy="0 1.5 0" xyz="-0.1 0.1 0"/>
            <material name="black"/>
        </visual>
    </link>
    <link name="link_3">
        <visual>
            <geometry>
                <cylinder radius="0.05" length="0.05"/>  
            </geometry>
            <origin rpy="0 1.5 0" xyz="0.1 -0.1 0"/>
            <material name="black"/>
        </visual>
    </link>
    <link name="link_4">
        <visual>
            <geometry>
                <cylinder radius="0.05" length="0.05"/>  
            </geometry>
            <origin rpy="0 1.5 0" xyz="-0.1 -0.1 0"/>
            <material name="black"/>
        </visual>
    </link>
    <joint name="base_to_link1" type="continuous">
        <parent link="base_link"/>
        <child link="link_1"/>
        <origin xyz="0 0 0"/>
    </joint>
    <joint name="base_to_link2" type="continuous">
        <parent link="base_link"/>
        <child link="link_2"/>
        <origin xyz="0 0 0"/>
    </joint>
    <joint name="base_to_link3" type="continuous">
        <parent link="base_link"/>
        <child link="link_3"/>
        <origin xyz="0 0 0"/>
    </joint>
        <joint name="base_to_link4" type="continuous">
        <parent link="base_link"/>
        <child link="link_4"/>
        <origin xyz="0 0 0"/>
    </joint>
    <!-- fin comentario -->
    <!-- manipulador -->
    <link name="arm_base">
        <visual>
            <geometry>
                <box size="0.1 .1 .1"/>
            </geometry>
            <origin rpy="0 0 0" xyz="0 0 0.1"/>
            <material name="white">
                <color rgba="1 1 1 1"/>
            </material>
        </visual>
        <collision>
            <geometry>
                <box size="0.1 .1 .1"/> 
            </geometry>
        </collision>    
    </link>
    <joint name="base_to_arm_base" type="continuous">
        <parent link="base_link"/>
        <child link="arm_base"/>
        <axis xyz="0 0 1"/>
        <origin xyz="0 0 0"/>
    </joint>
    <link name="arm_1">
        <visual>
            <geometry>
                <box size="0.05 .05 0.5"/>
            </geometry>
            <origin rpy="0 0 0" xyz="0 0 0.25"/>
            <material name="white">
                <color rgba="1 1 1 1"/>
            </material>
        </visual>
        <collision>
            <geometry>
                <box size="0.05 .05 0.5"/> 
            </geometry>
        </collision>    
    </link>
    <joint name="arm_1_to_arm_base" type="revolute">
        <parent link="arm_base"/>
        <child link="arm_1"/>
        <axis xyz="1 0 0"/>
        <origin xyz="0 0 0.15"/>
        <limit effort="1000.00" lower="-1.0" upper="1.0" velocity="0.5"/>
    </joint>
    <link name="arm_2">
        <visual>
            <geometry>
                <box size="0.05 0.05 0.5"/>
            </geometry>
            <origin rpy="0 0 0" xyz="0.06 0 0.15"/>
            <material name="white">
                <color rgba="1 1 1 1"/>
            </material>
        </visual>
        <collision>
            <geometry>
                <box size="0.05 .05 0.5"/> 
            </geometry>
        </collision>    
    </link>
    <joint name="arm_2_to_arm_1" type="revolute">
        <parent link="arm_1"/>
        <child link="arm_2"/>
        <axis xyz="1 0 0"/>
        <origin xyz="0.0 0 0.45"/>
        <limit effort="1000.0" lower="-2.5" upper="2.5" velocity="0.5"/>
    </joint>
    <joint name="left_gripper_joint" type="revolute">
        <axis xyz="0 0 1"/>
        <origin rpy="0 -1.57 0" xyz="0.06 0 0.4"/>
        <parent link="arm_2"/>
        <child link="left_gripper"/>
        <limit effort="1000.0" lower="0.0" upper="0.548" velocity="0.5"/>
    </joint>
    <link name="left_gripper">
        <visual>
            <origin rpy="0 0 0" xyz="0 0 0"/>
            <geometry>
                <mesh filename="package://robot1_description/meshes/gripper_v0/l_finger.dae"/>
            </geometry>
        </visual>
        <collision>
            <geometry>
                <box size="0.1 0.1 0.1"/> 
            </geometry>
        </collision>    
    </link>
    <joint name="left_tip_joint" type="fixed">
        <parent link="left_gripper"/>
        <child link="left_tip"/>
    </joint>
    <link name="left_tip">
        <visual>
            <origin rpy="0.0 0 0" xyz="0.09137 0.00495 0"/>
            <geometry>
                <mesh filename="package://robot1_description/meshes/gripper_v0/l_finger_tip.dae"/>
            </geometry>
        </visual>
        <collision>
            <geometry>
                <box size="0.1 0.1 0.1"/> 
            </geometry>
        </collision>    
    </link>
    <joint name="right_gripper_joint" type="revolute">
        <axis xyz="0 0 -1"/>
        <origin rpy="0 -1.57 0" xyz="0.06 0 0.4"/>
        <parent link="arm_2"/>
        <child link="right_gripper"/>
        <limit effort="1000.0" lower="0.0" upper="0.548" velocity="0.5"/>
    </joint>
    <link name="right_gripper">
        <visual>
            <origin rpy="-3.1415 0 0" xyz="0 0 0"/>
            <geometry>
                <mesh filename="package://robot1_description/meshes/gripper_v0/l_finger.dae"/>
            </geometry>
        </visual>
        <collision>
            <geometry>
                <box size="0.1 0.1 0.1"/> 
            </geometry>
        </collision>    
    </link>
    <joint name="right_tip_joint" type="fixed">
        <parent link="right_gripper"/>
        <child link="right_tip"/>
    </joint>
    <link name="right_tip">
        <visual>
            <origin rpy="-3.1415 0 0" xyz="0.09137 0.00495 0"/>
            <geometry>
                <mesh filename="package://robot1_description/meshes/gripper_v0/l_finger_tip.dae"/>
            </geometry>
        </visual>
        <collision>
            <geometry>
                <box size="0.1 0.1 0.1"/> 
            </geometry>
        </collision>    
    </link>
    <!-- fin manipulador -->    
</robot>